<?xml version="1.0"?>
<robot name="aubo_i10">

  <material name="blue">
    <color rgba="0 0 0.8 1"/>
  </material>
  
  <!-- BASE -->
  <link name="base">
    <visual>
      <geometry>
        <mesh filename="package://aubo_i10_description/meshes/I10_Base.stl"/>
      </geometry>
      <material name="blue"/>
    </visual>
    <collision>
      <geometry>
        <mesh filename="package://aubo_i10_description/meshes/I10_Base.stl"/>
      </geometry>
    </collision>
  </link>

  <!-- JOINT 1 -->
  <joint name="joint1" type="revolute">
    <parent link="base"/>
    <child link="joint1_link"/>
    <origin xyz="0 0 0.05" rpy="0 0 0"/>
    <axis xyz="0 0 1"/>
    <limit lower="-3.054" upper="3.054" velocity="2.618"/>
  </joint>

  <link name="joint1_link">
    <visual>
      <geometry>
        <mesh filename="package://aubo_i10_description/meshes/I10_Joint_1.stl"/>
      </geometry>
      <material name="blue"/>
    </visual>
    <collision>
      <geometry>
        <mesh filename="package://aubo_i10_description/meshes/I10_Joint_1.stl"/>
      </geometry>
    </collision>
  </link>

  <!-- JOINT 2 -->
  <joint name="joint2" type="revolute">
    <parent link="joint1_link"/>
    <child link="joint2_link"/>
    <origin xyz="0 0 0.40" rpy="0 0 0"/>
    <axis xyz="0 1 0"/>
    <limit lower="-3.054" upper="3.054" velocity="3.142"/>
  </joint>

  <link name="joint2_link">
    <visual>
      <geometry>
        <mesh filename="package://aubo_i10_description/meshes/I10_Joint_2.stl"/>
      </geometry>
      <material name="blue"/>
    </visual>
    <collision>
      <geometry>
        <mesh filename="package://aubo_i10_description/meshes/I10_Joint_2.stl"/>
      </geometry>
    </collision>
  </link>

  <!-- JOINT 3 -->
  <joint name="joint3" type="revolute">
    <parent link="joint2_link"/>
    <child link="joint3_link"/>
    <origin xyz="0 0 0.30" rpy="0 0 0"/>
    <axis xyz="0 1 0"/>
    <limit lower="-3.054" upper="3.054" velocity="2.618"/>
  </joint>

  <link name="joint3_link">
    <visual>
      <geometry>
        <mesh filename="package://aubo_i10_description/meshes/I10_Joint_3.stl"/>
      </geometry>
      <material name="blue"/>
    </visual>
    <collision>
      <geometry>
        <mesh filename="package://aubo_i10_description/meshes/I10_Joint_3.stl"/>
      </geometry>
    </collision>
  </link>

  <!-- JOINT 4 -->
  <joint name="joint4" type="revolute">
    <parent link="joint3_link"/>
    <child link="joint4_link"/>
    <origin xyz="0 0 0.25" rpy="0 0 0"/>
    <axis xyz="1 0 0"/>
    <limit lower="-3.054" upper="3.054" velocity="3.142"/>
  </joint>

  <link name="joint4_link">
    <visual>
      <geometry>
        <mesh filename="package://aubo_i10_description/meshes/I10_Joint_4.stl"/>
      </geometry>
      <material name="blue"/>
    </visual>
    <collision>
      <geometry>
        <mesh filename="package://aubo_i10_description/meshes/I10_Joint_4.stl"/>
      </geometry>
    </collision>
  </link>

  <!-- JOINT 5 -->
  <joint name="joint5" type="revolute">
    <parent link="joint4_link"/>
    <child link="joint5_link"/>
    <origin xyz="0 0 0.20" rpy="0 0 0"/>
    <axis xyz="0 1 0"/>
    <limit lower="-3.054" upper="3.054" velocity="3.142"/>
  </joint>

  <link name="joint5_link">
    <visual>
      <geometry>
        <mesh filename="package://aubo_i10_description/meshes/I10_Joint_5.stl"/>
      </geometry>
      <material name="blue"/>
    </visual>
    <collision>
      <geometry>
        <mesh filename="package://aubo_i10_description/meshes/I10_Joint_5.stl"/>
      </geometry>
    </collision>
  </link>

  <!-- JOINT 6 -->
  <joint name="joint6" type="revolute">
    <parent link="joint5_link"/>
    <child link="joint6_link"/>
    <origin xyz="0 0 0.15" rpy="0 0 0"/>
    <axis xyz="1 0 0"/>
    <limit lower="-3.054" upper="3.054" velocity="3.142"/>
  </joint>

  <link name="joint6_link">
    <visual>
      <geometry>
        <mesh filename="package://aubo_i10_description/meshes/I10_Joint_6.stl"/>
      </geometry>
      <material name="blue"/>
    </visual>
    <collision>
      <geometry>
        <mesh filename="package://aubo_i10_description/meshes/I10_Joint_6.stl"/>
      </geometry>
    </collision>
  </link>

</robot>
