<?xml version="1.0"?>
<robot name="AUBO_I10" xmlns:xacro="http://www.ros.org/wiki/xacro">

  <!-- ==================== BASE ==================== -->
  <link name="base_link">
    <inertial>
      <mass value="10"/>
      <inertia ixx="0.1" ixy="0.0" ixz="0.0"
               iyy="0.1" iyz="0.0"
               izz="0.1"/>
    </inertial>
    <visual>
      <geometry>
        <mesh filename="package://3D_model/AUBO_I10/meshes/I10i10_base.stl" scale="1 1 1"/>
      </geometry>
      <material name="blue"/>
    </visual>
    <collision>
      <geometry>
        <mesh filename="package://3D_model/AUBO_I10/meshes/I10i10_base.stl" scale="1 1 1"/>
      </geometry>
    </collision>
  </link>

  <!-- ==================== LINK1 ==================== -->
  <link name="link1">
    <inertial>
      <mass value="5"/>
      <inertia ixx="0.05" ixy="0.0" ixz="0.0"
               iyy="0.05" iyz="0.0"
               izz="0.05"/>
    </inertial>
    <visual>
      <geometry>
        <mesh filename="package://3D_model/AUBO_I10/meshes/I10i10_arm_1.stl" scale="1 1 1"/>
      </geometry>
      <material name="blue"/>
    </visual>
    <collision>
      <geometry>
        <mesh filename="package://3D_model/AUBO_I10/meshes/I10i10_arm_1.stl" scale="1 1 1"/>
      </geometry>
    </collision>
  </link>

  <joint name="joint1" type="revolute">
    <parent link="base_link"/>
    <child link="link1"/>
    <origin xyz="0 0 0.1" rpy="0 0 0"/>
    <axis xyz="0 0 1"/>
    <limit lower="-3.14" upper="3.14" effort="50" velocity="1.0"/>
  </joint>

  <!-- ==================== LINK2 ==================== -->
  <link name="link2">
    <inertial>
      <mass value="4"/>
      <inertia ixx="0.04" ixy="0.0" ixz="0.0"
               iyy="0.04" iyz="0.0"
               izz="0.04"/>
    </inertial>
    <visual>
      <geometry>
        <mesh filename="package://3D_model/AUBO_I10/meshes/I10i10_arm_2.stl" scale="1 1 1"/>
      </geometry>
      <material name="blue"/>
    </visual>
    <collision>
      <geometry>
        <mesh filename="package://3D_model/AUBO_I10/meshes/I10i10_arm_2.stl" scale="1 1 1"/>
      </geometry>
    </collision>
  </link>

  <joint name="joint2" type="revolute">
    <parent link="link1"/>
    <child link="link2"/>
    <origin xyz="0 0 0.2" rpy="0 0 0"/>
    <axis xyz="0 1 0"/>
    <limit lower="-3.14" upper="3.14" effort="50" velocity="1.0"/>
  </joint>

  <!-- ==================== LINK3 ==================== -->
  <link name="link3">
    <inertial>
      <mass value="3.5"/>
      <inertia ixx="0.035" ixy="0.0" ixz="0.0"
               iyy="0.035" iyz="0.0"
               izz="0.035"/>
    </inertial>
    <visual>
      <geometry>
        <mesh filename="package://3D_model/AUBO_I10/meshes/I10Mesh.001.stl" scale="1 1 1"/>
      </geometry>
    </visual>
    <collision>
      <geometry>
        <mesh filename="package://3D_model/AUBO_I10/meshes/I10Mesh.001.stl" scale="1 1 1"/>
      </geometry>
    </collision>
  </link>

  <joint name="joint3" type="revolute">
    <parent link="link2"/>
    <child link="link3"/>
    <origin xyz="0 0 0.2" rpy="0 0 0"/>
    <axis xyz="0 1 0"/>
    <limit lower="-3.14" upper="3.14" effort="50" velocity="1.0"/>
  </joint>

  <!-- ==================== LINK4 ==================== -->
  <link name="link4">
    <inertial>
      <mass value="3"/>
      <inertia ixx="0.03" ixy="0.0" ixz="0.0"
               iyy="0.03" iyz="0.0"
               izz="0.03"/>
    </inertial>
    <visual>
      <geometry>
        <mesh filename="package://3D_model/AUBO_I10/meshes/I10Mesh.002.stl" scale="1 1 1"/>
      </geometry>
    </visual>
    <collision>
      <geometry>
        <mesh filename="package://3D_model/AUBO_I10/meshes/I10Mesh.002.stl" scale="1 1 1"/>
      </geometry>
    </collision>
  </link>

  <joint name="joint4" type="revolute">
    <parent link="link3"/>
    <child link="link4"/>
    <origin xyz="0 0 0.2" rpy="0 0 0"/>
    <axis xyz="0 1 0"/>
    <limit lower="-3.14" upper="3.14" effort="50" velocity="1.0"/>
  </joint>

  <!-- ==================== LINK5 ==================== -->
  <link name="link5">
    <inertial>
      <mass value="2.5"/>
      <inertia ixx="0.025" ixy="0.0" ixz="0.0"
               iyy="0.025" iyz="0.0"
               izz="0.025"/>
    </inertial>
    <visual>
      <geometry>
        <mesh filename="package://3D_model/AUBO_I10/meshes/I10Mesh.003.stl" scale="1 1 1"/>
      </geometry>
    </visual>
    <collision>
      <geometry>
        <mesh filename="package://3D_model/AUBO_I10/meshes/I10Mesh.003.stl" scale="1 1 1"/>
      </geometry>
    </collision>
  </link>

  <joint name="joint5" type="revolute">
    <parent link="link4"/>
    <child link="link5"/>
    <origin xyz="0 0 0.15" rpy="0 0 0"/>
    <axis xyz="0 1 0"/>
    <limit lower="-3.14" upper="3.14" effort="50" velocity="1.0"/>
  </joint>

  <!-- ==================== LINK6 ==================== -->
  <link name="link6">
    <inertial>
      <mass value="2"/>
      <inertia ixx="0.02" ixy="0.0" ixz="0.0"
               iyy="0.02" iyz="0.0"
               izz="0.02"/>
    </inertial>
    <visual>
      <geometry>
        <mesh filename="package://3D_model/AUBO_I10/meshes/I10Mesh.004.stl" scale="1 1 1"/>
      </geometry>
    </visual>
    <collision>
      <geometry>
        <mesh filename="package://3D_model/AUBO_I10/meshes/I10Mesh.004.stl" scale="1 1 1"/>
      </geometry>
    </collision>
  </link>

  <joint name="joint6" type="revolute">
    <parent link="link5"/>
    <child link="link6"/>
    <origin xyz="0 0 0.1" rpy="0 0 0"/>
    <axis xyz="0 1 0"/>
    <limit lower="-3.14" upper="3.14" effort="50" velocity="1.0"/>
  </joint>
  <!-- ==================== LINK7 ==================== -->
  <link name="link7">
    <inertial>
      <mass value="1.2"/>
      <inertia ixx="0.012" ixy="0" ixz="0"
               iyy="0.012" iyz="0" izz="0.012"/>
    </inertial>
    <visual>
      <geometry>
        <mesh filename="package://3D_model/AUBO_I10/meshes/I10Mesh.006.stl" scale="1 1 1"/>
      </geometry>
    </visual>
    <collision>
      <geometry>
        <mesh filename="package://3D_model/AUBO_I10/meshes/I10Mesh.006.stl" scale="1 1 1"/>
      </geometry>
    </collision>
  </link>

  <joint name="joint7" type="fixed">
    <parent link="link6"/>
    <child link="link7"/>
    <origin xyz="0 0 0" rpy="0 0 0"/>
  </joint>

  <!-- ==================== LINK8 ==================== -->
  <link name="link8">
    <inertial>
      <mass value="1.2"/>
      <inertia ixx="0.012" ixy="0" ixz="0"
               iyy="0.012" iyz="0" izz="0.012"/>
    </inertial>
    <visual>
      <geometry>
        <mesh filename="package://3D_model/AUBO_I10/meshes/I10Mesh.007.stl" scale="1 1 1"/>
      </geometry>
    </visual>
    <collision>
      <geometry>
        <mesh filename="package://3D_model/AUBO_I10/meshes/I10Mesh.007.stl" scale="1 1 1"/>
      </geometry>
    </collision>
  </link>

  <joint name="joint8" type="fixed">
    <parent link="link7"/>
    <child link="link8"/>
    <origin xyz="0 0 0" rpy="0 0 0"/>
  </joint>

  <!-- ==================== LINK9 ==================== -->
  <link name="link9">
    <inertial>
      <mass value="1"/>
      <inertia ixx="0.01" ixy="0" ixz="0"
               iyy="0.01" iyz="0" izz="0.01"/>
    </inertial>
    <visual>
      <geometry>
        <mesh filename="package://3D_model/AUBO_I10/meshes/I10Mesh.008.stl" scale="1 1 1"/>
      </geometry>
    </visual>
    <collision>
      <geometry>
        <mesh filename="package://3D_model/AUBO_I10/meshes/I10Mesh.008.stl" scale="1 1 1"/>
      </geometry>
    </collision>
  </link>

  <joint name="joint9" type="fixed">
    <parent link="link8"/>
    <child link="link9"/>
    <origin xyz="0 0 0" rpy="0 0 0"/>
  </joint>

  <!-- ==================== LINK10 ==================== -->
  <link name="link10">
    <inertial>
      <mass value="1"/>
      <inertia ixx="0.01" ixy="0" ixz="0"
               iyy="0.01" iyz="0" izz="0.01"/>
    </inertial>
    <visual>
      <geometry>
        <mesh filename="package://3D_model/AUBO_I10/meshes/I10Mesh.009.stl" scale="1 1 1"/>
      </geometry>
    </visual>
    <collision>
      <geometry>
        <mesh filename="package://3D_model/AUBO_I10/meshes/I10Mesh.009.stl" scale="1 1 1"/>
      </geometry>
    </collision>
  </link>

  <joint name="joint10" type="fixed">
    <parent link="link9"/>
    <child link="link10"/>
    <origin xyz="0 0 0" rpy="0 0 0"/>
  </joint>

  <!-- ==================== LINK11 ==================== -->
  <link name="link11">
    <inertial>
      <mass value="1"/>
      <inertia ixx="0.01" ixy="0" ixz="0"
               iyy="0.01" iyz="0" izz="0.01"/>
    </inertial>
    <visual>
      <geometry>
        <mesh filename="package://3D_model/AUBO_I10/meshes/I10Mesh.010.stl" scale="1 1 1"/>
      </geometry>
    </visual>
    <collision>
      <geometry>
        <mesh filename="package://3D_model/AUBO_I10/meshes/I10Mesh.010.stl" scale="1 1 1"/>
      </geometry>
    </collision>
  </link>

  <joint name="joint11" type="fixed">
    <parent link="link10"/>
    <child link="link11"/>
    <origin xyz="0 0 0" rpy="0 0 0"/>
  </joint>

  <!-- ==================== LINK12 ==================== -->
  <link name="link12">
    <inertial>
      <mass value="0.8"/>
      <inertia ixx="0.008" ixy="0" ixz="0"
               iyy="0.008" iyz="0" izz="0.008"/>
    </inertial>
    <visual>
      <geometry>
        <mesh filename="package://3D_model/AUBO_I10/meshes/I10Mesh.011.stl" scale="1 1 1"/>
      </geometry>
    </visual>
    <collision>
      <geometry>
        <mesh filename="package://3D_model/AUBO_I10/meshes/I10Mesh.011.stl" scale="1 1 1"/>
      </geometry>
    </collision>
  </link>

  <joint name="joint12" type="fixed">
    <parent link="link11"/>
    <child link="link12"/>
    <origin xyz="0 0 0" rpy="0 0 0"/>
  </joint>

  <!-- ==================== LINK13 ==================== -->
  <link name="link13">
    <inertial>
      <mass value="0.8"/>
      <inertia ixx="0.008" ixy="0" ixz="0"
               iyy="0.008" iyz="0" izz="0.008"/>
    </inertial>
    <visual>
      <geometry>
        <mesh filename="package://3D_model/AUBO_I10/meshes/I10Mesh.012.stl" scale="1 1 1"/>
      </geometry>
    </visual>
    <collision>
      <geometry>
        <mesh filename="package://3D_model/AUBO_I10/meshes/I10Mesh.012.stl" scale="1 1 1"/>
      </geometry>
    </collision>
  </link>

  <joint name="joint13" type="fixed">
    <parent link="link12"/>
    <child link="link13"/>
    <origin xyz="0 0 0" rpy="0 0 0"/>
  </joint>

  <!-- ==================== LINK14 ==================== -->
  <link name="link14">
    <inertial>
      <mass value="0.8"/>
      <inertia ixx="0.008" ixy="0" ixz="0"
               iyy="0.008" iyz="0" izz="0.008"/>
    </inertial>
    <visual>
      <geometry>
        <mesh filename="package://3D_model/AUBO_I10/meshes/I10Mesh.013.stl" scale="1 1 1"/>
      </geometry>
    </visual>
    <collision>
      <geometry>
        <mesh filename="package://3D_model/AUBO_I10/meshes/I10Mesh.013.stl" scale="1 1 1"/>
      </geometry>
    </collision>
  </link>

  <joint name="joint14" type="fixed">
    <parent link="link13"/>
    <child link="link14"/>
    <origin xyz="0 0 0" rpy="0 0 0"/>
  </joint>
  <!-- ==================== LINK15 ==================== -->
  <link name="link15">
    <inertial>
      <mass value="0.7"/>
      <inertia ixx="0.007" ixy="0" ixz="0"
               iyy="0.007" iyz="0" izz="0.007"/>
    </inertial>
    <visual>
      <geometry>
        <mesh filename="package://3D_model/AUBO_I10/meshes/I10Mesh.014.stl" scale="1 1 1"/>
      </geometry>
    </visual>
    <collision>
      <geometry>
        <mesh filename="package://3D_model/AUBO_I10/meshes/I10Mesh.014.stl" scale="1 1 1"/>
      </geometry>
    </collision>
  </link>

  <joint name="joint15" type="fixed">
    <parent link="link14"/>
    <child link="link15"/>
    <origin xyz="0 0 0" rpy="0 0 0"/>
  </joint>

  <!-- ==================== LINK16 ==================== -->
  <link name="link16">
    <inertial>
      <mass value="0.7"/>
      <inertia ixx="0.007" ixy="0" ixz="0"
               iyy="0.007" iyz="0" izz="0.007"/>
    </inertial>
    <visual>
      <geometry>
        <mesh filename="package://3D_model/AUBO_I10/meshes/I10Mesh.015.stl" scale="1 1 1"/>
      </geometry>
    </visual>
    <collision>
      <geometry>
        <mesh filename="package://3D_model/AUBO_I10/meshes/I10Mesh.015.stl" scale="1 1 1"/>
      </geometry>
    </collision>
  </link>

  <joint name="joint16" type="fixed">
    <parent link="link15"/>
    <child link="link16"/>
    <origin xyz="0 0 0" rpy="0 0 0"/>
  </joint>

  <!-- ==================== LINK17 ==================== -->
  <link name="link17">
    <inertial>
      <mass value="0.6"/>
      <inertia ixx="0.006" ixy="0" ixz="0"
               iyy="0.006" iyz="0" izz="0.006"/>
    </inertial>
    <visual>
      <geometry>
        <mesh filename="package://3D_model/AUBO_I10/meshes/I10Mesh.016.stl" scale="1 1 1"/>
      </geometry>
    </visual>
    <collision>
      <geometry>
        <mesh filename="package://3D_model/AUBO_I10/meshes/I10Mesh.016.stl" scale="1 1 1"/>
      </geometry>
    </collision>
  </link>

  <joint name="joint17" type="fixed">
    <parent link="link16"/>
    <child link="link17"/>
    <origin xyz="0 0 0" rpy="0 0 0"/>
  </joint>

  <!-- ==================== LINK18 ==================== -->
  <link name="link18">
    <inertial>
      <mass value="0.6"/>
      <inertia ixx="0.006" ixy="0" ixz="0"
               iyy="0.006" iyz="0" izz="0.006"/>
    </inertial>
    <visual>
      <geometry>
        <mesh filename="package://3D_model/AUBO_I10/meshes/I10Mesh.017.stl" scale="1 1 1"/>
      </geometry>
    </visual>
    <collision>
      <geometry>
        <mesh filename="package://3D_model/AUBO_I10/meshes/I10Mesh.017.stl" scale="1 1 1"/>
      </geometry>
    </collision>
  </link>

  <joint name="joint18" type="fixed">
    <parent link="link17"/>
    <child link="link18"/>
    <origin xyz="0 0 0" rpy="0 0 0"/>
  </joint>

  <!-- ==================== LINK19 ==================== -->
  <link name="link19">
    <inertial>
      <mass value="0.5"/>
      <inertia ixx="0.005" ixy="0" ixz="0"
               iyy="0.005" iyz="0" izz="0.005"/>
    </inertial>
    <visual>
      <geometry>
        <mesh filename="package://3D_model/AUBO_I10/meshes/I10Mesh.018.stl" scale="1 1 1"/>
      </geometry>
    </visual>
    <collision>
      <geometry>
        <mesh filename="package://3D_model/AUBO_I10/meshes/I10Mesh.018.stl" scale="1 1 1"/>
      </geometry>
    </collision>
  </link>

  <joint name="joint19" type="fixed">
    <parent link="link18"/>
    <child link="link19"/>
    <origin xyz="0 0 0" rpy="0 0 0"/>
  </joint>

  <!-- ==================== LINK20 ==================== -->
  <link name="link20">
    <inertial>
      <mass value="0.5"/>
      <inertia ixx="0.005" ixy="0" ixz="0"
               iyy="0.005" iyz="0" izz="0.005"/>
    </inertial>
    <visual>
      <geometry>
        <mesh filename="package://3D_model/AUBO_I10/meshes/I10Mesh.019.stl" scale="1 1 1"/>
      </geometry>
    </visual>
    <collision>
      <geometry>
        <mesh filename="package://3D_model/AUBO_I10/meshes/I10Mesh.019.stl" scale="1 1 1"/>
      </geometry>
    </collision>
  </link>

  <joint name="joint20" type="fixed">
    <parent link="link19"/>
    <child link="link20"/>
    <origin xyz="0 0 0" rpy="0 0 0"/>
  </joint>

  <!-- ==================== LINK21 ==================== -->
  <link name="link21">
    <inertial>
      <mass value="0.4"/>
      <inertia ixx="0.004" ixy="0" ixz="0"
               iyy="0.004" iyz="0" izz="0.004"/>
    </inertial>
    <visual>
      <geometry>
        <mesh filename="package://3D_model/AUBO_I10/meshes/I10Mesh.020.stl" scale="1 1 1"/>
      </geometry>
    </visual>
    <collision>
      <geometry>
        <mesh filename="package://3D_model/AUBO_I10/meshes/I10Mesh.020.stl" scale="1 1 1"/>
      </geometry>
    </collision>
  </link>

  <joint name="joint21" type="fixed">
    <parent link="link20"/>
    <child link="link21"/>
    <origin xyz="0 0 0" rpy="0 0 0"/>
  </joint>

  <!-- ==================== LINK22 ==================== -->
  <link name="link22">
    <inertial>
      <mass value="0.4"/>
      <inertia ixx="0.004" ixy="0" ixz="0"
               iyy="0.004" iyz="0" izz="0.004"/>
    </inertial>
    <visual>
      <geometry>
        <mesh filename="package://3D_model/AUBO_I10/meshes/I10Mesh.021.stl" scale="1 1 1"/>
      </geometry>
    </visual>
    <collision>
      <geometry>
        <mesh filename="package://3D_model/AUBO_I10/meshes/I10Mesh.021.stl" scale="1 1 1"/>
      </geometry>
    </collision>
  </link>

  <joint name="joint22" type="fixed">
    <parent link="link21"/>
    <child link="link22"/>
    <origin xyz="0 0 0" rpy="0 0 0"/>
  </joint>
  <!-- ==================== LINK15 ==================== -->
  <link name="link15">
    <inertial>
      <mass value="0.7"/>
      <inertia ixx="0.007" ixy="0" ixz="0"
               iyy="0.007" iyz="0" izz="0.007"/>
    </inertial>
    <visual>
      <geometry>
        <mesh filename="package://3D_model/AUBO_I10/meshes/I10Mesh.014.stl" scale="1 1 1"/>
      </geometry>
    </visual>
    <collision>
      <geometry>
        <mesh filename="package://3D_model/AUBO_I10/meshes/I10Mesh.014.stl" scale="1 1 1"/>
      </geometry>
    </collision>
  </link>

  <joint name="joint15" type="fixed">
    <parent link="link14"/>
    <child link="link15"/>
    <origin xyz="0 0 0" rpy="0 0 0"/>
  </joint>

  <!-- ==================== LINK16 ==================== -->
  <link name="link16">
    <inertial>
      <mass value="0.7"/>
      <inertia ixx="0.007" ixy="0" ixz="0"
               iyy="0.007" iyz="0" izz="0.007"/>
    </inertial>
    <visual>
      <geometry>
        <mesh filename="package://3D_model/AUBO_I10/meshes/I10Mesh.015.stl" scale="1 1 1"/>
      </geometry>
    </visual>
    <collision>
      <geometry>
        <mesh filename="package://3D_model/AUBO_I10/meshes/I10Mesh.015.stl" scale="1 1 1"/>
      </geometry>
    </collision>
  </link>

  <joint name="joint16" type="fixed">
    <parent link="link15"/>
    <child link="link16"/>
    <origin xyz="0 0 0" rpy="0 0 0"/>
  </joint>

  <!-- ==================== LINK17 ==================== -->
  <link name="link17">
    <inertial>
      <mass value="0.6"/>
      <inertia ixx="0.006" ixy="0" ixz="0"
               iyy="0.006" iyz="0" izz="0.006"/>
    </inertial>
    <visual>
      <geometry>
        <mesh filename="package://3D_model/AUBO_I10/meshes/I10Mesh.016.stl" scale="1 1 1"/>
      </geometry>
    </visual>
    <collision>
      <geometry>
        <mesh filename="package://3D_model/AUBO_I10/meshes/I10Mesh.016.stl" scale="1 1 1"/>
      </geometry>
    </collision>
  </link>

  <joint name="joint17" type="fixed">
    <parent link="link16"/>
    <child link="link17"/>
    <origin xyz="0 0 0" rpy="0 0 0"/>
  </joint>

  <!-- ==================== LINK18 ==================== -->
  <link name="link18">
    <inertial>
      <mass value="0.6"/>
      <inertia ixx="0.006" ixy="0" ixz="0"
               iyy="0.006" iyz="0" izz="0.006"/>
    </inertial>
    <visual>
      <geometry>
        <mesh filename="package://3D_model/AUBO_I10/meshes/I10Mesh.017.stl" scale="1 1 1"/>
      </geometry>
    </visual>
    <collision>
      <geometry>
        <mesh filename="package://3D_model/AUBO_I10/meshes/I10Mesh.017.stl" scale="1 1 1"/>
      </geometry>
    </collision>
  </link>

  <joint name="joint18" type="fixed">
    <parent link="link17"/>
    <child link="link18"/>
    <origin xyz="0 0 0" rpy="0 0 0"/>
  </joint>

  <!-- ==================== LINK19 ==================== -->
  <link name="link19">
    <inertial>
      <mass value="0.5"/>
      <inertia ixx="0.005" ixy="0" ixz="0"
               iyy="0.005" iyz="0" izz="0.005"/>
    </inertial>
    <visual>
      <geometry>
        <mesh filename="package://3D_model/AUBO_I10/meshes/I10Mesh.018.stl" scale="1 1 1"/>
      </geometry>
    </visual>
    <collision>
      <geometry>
        <mesh filename="package://3D_model/AUBO_I10/meshes/I10Mesh.018.stl" scale="1 1 1"/>
      </geometry>
    </collision>
  </link>

  <joint name="joint19" type="fixed">
    <parent link="link18"/>
    <child link="link19"/>
    <origin xyz="0 0 0" rpy="0 0 0"/>
  </joint>

  <!-- ==================== LINK20 ==================== -->
  <link name="link20">
    <inertial>
      <mass value="0.5"/>
      <inertia ixx="0.005" ixy="0" ixz="0"
               iyy="0.005" iyz="0" izz="0.005"/>
    </inertial>
    <visual>
      <geometry>
        <mesh filename="package://3D_model/AUBO_I10/meshes/I10Mesh.019.stl" scale="1 1 1"/>
      </geometry>
    </visual>
    <collision>
      <geometry>
        <mesh filename="package://3D_model/AUBO_I10/meshes/I10Mesh.019.stl" scale="1 1 1"/>
      </geometry>
    </collision>
  </link>

  <joint name="joint20" type="fixed">
    <parent link="link19"/>
    <child link="link20"/>
    <origin xyz="0 0 0" rpy="0 0 0"/>
  </joint>

  <!-- ==================== LINK21 ==================== -->
  <link name="link21">
    <inertial>
      <mass value="0.4"/>
      <inertia ixx="0.004" ixy="0" ixz="0"
               iyy="0.004" iyz="0" izz="0.004"/>
    </inertial>
    <visual>
      <geometry>
        <mesh filename="package://3D_model/AUBO_I10/meshes/I10Mesh.020.stl" scale="1 1 1"/>
      </geometry>
    </visual>
    <collision>
      <geometry>
        <mesh filename="package://3D_model/AUBO_I10/meshes/I10Mesh.020.stl" scale="1 1 1"/>
      </geometry>
    </collision>
  </link>

  <joint name="joint21" type="fixed">
    <parent link="link20"/>
    <child link="link21"/>
    <origin xyz="0 0 0" rpy="0 0 0"/>
  </joint>

  <!-- ==================== LINK22 ==================== -->
  <link name="link22">
    <inertial>
      <mass value="0.4"/>
      <inertia ixx="0.004" ixy="0" ixz="0"
               iyy="0.004" iyz="0" izz="0.004"/>
    </inertial>
    <visual>
      <geometry>
        <mesh filename="package://3D_model/AUBO_I10/meshes/I10Mesh.021.stl" scale="1 1 1"/>
      </geometry>
    </visual>
    <collision>
      <geometry>
        <mesh filename="package://3D_model/AUBO_I10/meshes/I10Mesh.021.stl" scale="1 1 1"/>
      </geometry>
    </collision>
  </link>

  <joint name="joint22" type="fixed">
    <parent link="link21"/>
    <child link="link22"/>
    <origin xyz="0 0 0" rpy="0 0 0"/>
  </joint>
  <!-- ==================== LINK23 ==================== -->
  <link name="link23">
    <inertial>
      <mass value="0.35"/>
      <inertia ixx="0.0035" ixy="0" ixz="0"
               iyy="0.0035" iyz="0" izz="0.0035"/>
    </inertial>
    <visual>
      <geometry>
        <mesh filename="package://3D_model/AUBO_I10/meshes/I10Mesh.022.stl" scale="1 1 1"/>
      </geometry>
    </visual>
    <collision>
      <geometry>
        <mesh filename="package://3D_model/AUBO_I10/meshes/I10Mesh.022.stl" scale="1 1 1"/>
      </geometry>
    </collision>
  </link>

  <joint name="joint23" type="fixed">
    <parent link="link22"/>
    <child link="link23"/>
    <origin xyz="0 0 0" rpy="0 0 0"/>
  </joint>

  <!-- ==================== LINK24 ==================== -->
  <link name="link24">
    <inertial>
      <mass value="0.35"/>
      <inertia ixx="0.0035" ixy="0" ixz="0"
               iyy="0.0035" iyz="0" izz="0.0035"/>
    </inertial>
    <visual>
      <geometry>
        <mesh filename="package://3D_model/AUBO_I10/meshes/I10Mesh.023.stl" scale="1 1 1"/>
      </geometry>
    </visual>
    <collision>
      <geometry>
        <mesh filename="package://3D_model/AUBO_I10/meshes/I10Mesh.023.stl" scale="1 1 1"/>
      </geometry>
    </collision>
  </link>

  <joint name="joint24" type="fixed">
    <parent link="link23"/>
    <child link="link24"/>
    <origin xyz="0 0 0" rpy="0 0 0"/>
  </joint>

  <!-- ==================== LINK25 ==================== -->
  <link name="link25">
    <inertial>
      <mass value="0.3"/>
      <inertia ixx="0.003" ixy="0" ixz="0"
               iyy="0.003" iyz="0" izz="0.003"/>
    </inertial>
    <visual>
      <geometry>
        <mesh filename="package://3D_model/AUBO_I10/meshes/I10Mesh.024.stl" scale="1 1 1"/>
      </geometry>
    </visual>
    <collision>
      <geometry>
        <mesh filename="package://3D_model/AUBO_I10/meshes/I10Mesh.024.stl" scale="1 1 1"/>
      </geometry>
    </collision>
  </link>

  <joint name="joint25" type="fixed">
    <parent link="link24"/>
    <child link="link25"/>
    <origin xyz="0 0 0" rpy="0 0 0"/>
  </joint>

  <!-- ==================== LINK26 ==================== -->
  <link name="link26">
    <inertial>
      <mass value="0.3"/>
      <inertia ixx="0.003" ixy="0" ixz="0"
               iyy="0.003" iyz="0" izz="0.003"/>
    </inertial>
    <visual>
      <geometry>
        <mesh filename="package://3D_model/AUBO_I10/meshes/I10Mesh.025.stl" scale="1 1 1"/>
      </geometry>
    </visual>
    <collision>
      <geometry>
        <mesh filename="package://3D_model/AUBO_I10/meshes/I10Mesh.025.stl" scale="1 1 1"/>
      </geometry>
    </collision>
  </link>

  <joint name="joint26" type="fixed">
    <parent link="link25"/>
    <child link="link26"/>
    <origin xyz="0 0 0" rpy="0 0 0"/>
  </joint>

  <!-- ==================== LINK27 ==================== -->
  <link name="link27">
    <inertial>
      <mass value="0.25"/>
      <inertia ixx="0.0025" ixy="0" ixz="0"
               iyy="0.0025" iyz="0" izz="0.0025"/>
    </inertial>
    <visual>
      <geometry>
        <mesh filename="package://3D_model/AUBO_I10/meshes/I10Mesh.026.stl" scale="1 1 1"/>
      </geometry>
    </visual>
    <collision>
      <geometry>
        <mesh filename="package://3D_model/AUBO_I10/meshes/I10Mesh.026.stl" scale="1 1 1"/>
      </geometry>
    </collision>
  </link>

  <joint name="joint27" type="fixed">
    <parent link="link26"/>
    <child link="link27"/>
    <origin xyz="0 0 0" rpy="0 0 0"/>
  </joint>
  <!-- ==================== LINK28 ==================== -->
  <link name="link28">
    <inertial>
      <mass value="0.25"/>
      <inertia ixx="0.0025" ixy="0" ixz="0"
               iyy="0.0025" iyz="0" izz="0.0025"/>
    </inertial>
    <visual>
      <geometry>
        <mesh filename="package://3D_model/AUBO_I10/meshes/I10Mesh.027.stl" scale="1 1 1"/>
      </geometry>
    </visual>
    <collision>
      <geometry>
        <mesh filename="package://3D_model/AUBO_I10/meshes/I10Mesh.027.stl" scale="1 1 1"/>
      </geometry>
    </collision>
  </link>

  <joint name="joint28" type="fixed">
    <parent link="link27"/>
    <child link="link28"/>
    <origin xyz="0 0 0" rpy="0 0 0"/>
  </joint>

  <!-- ==================== LINK29 ==================== -->
  <link name="link29">
    <inertial>
      <mass value="0.2"/>
      <inertia ixx="0.002" ixy="0" ixz="0"
               iyy="0.002" iyz="0" izz="0.002"/>
    </inertial>
    <visual>
      <geometry>
        <mesh filename="package://3D_model/AUBO_I10/meshes/I10Mesh.028.stl" scale="1 1 1"/>
      </geometry>
    </visual>
    <collision>
      <geometry>
        <mesh filename="package://3D_model/AUBO_I10/meshes/I10Mesh.028.stl" scale="1 1 1"/>
      </geometry>
    </collision>
  </link>

  <joint name="joint29" type="fixed">
    <parent link="link28"/>
    <child link="link29"/>
    <origin xyz="0 0 0" rpy="0 0 0"/>
  </joint>

  <!-- ==================== LINK30 ==================== -->
  <link name="link30">
    <inertial>
      <mass value="0.2"/>
      <inertia ixx="0.002" ixy="0" ixz="0"
               iyy="0.002" iyz="0" izz="0.002"/>
    </inertial>
    <visual>
      <geometry>
        <mesh filename="package://3D_model/AUBO_I10/meshes/I10Mesh.029.stl" scale="1 1 1"/>
      </geometry>
    </visual>
    <collision>
      <geometry>
        <mesh filename="package://3D_model/AUBO_I10/meshes/I10Mesh.029.stl" scale="1 1 1"/>
      </geometry>
    </collision>
  </link>

  <joint name="joint30" type="fixed">
    <parent link="link29"/>
    <child link="link30"/>
    <origin xyz="0 0 0" rpy="0 0 0"/>
  </joint>

  <!-- ==================== LINK31 ==================== -->
  <link name="link31">
    <inertial>
      <mass value="0.15"/>
      <inertia ixx="0.0015" ixy="0" ixz="0"
               iyy="0.0015" iyz="0" izz="0.0015"/>
    </inertial>
    <visual>
      <geometry>
        <mesh filename="package://3D_model/AUBO_I10/meshes/I10Mesh.030.stl" scale="1 1 1"/>
      </geometry>
    </visual>
    <collision>
      <geometry>
        <mesh filename="package://3D_model/AUBO_I10/meshes/I10Mesh.030.stl" scale="1 1 1"/>
      </geometry>
    </collision>
  </link>

  <joint name="joint31" type="fixed">
    <parent link="link30"/>
    <child link="link31"/>
    <origin xyz="0 0 0" rpy="0 0 0"/>
  </joint>

  <!-- ==================== LINK32 ==================== -->
  <link name="link32">
    <inertial>
      <mass value="0.15"/>
      <inertia ixx="0.0015" ixy="0" ixz="0"
               iyy="0.0015" iyz="0" izz="0.0015"/>
    </inertial>
    <visual>
      <geometry>
        <mesh filename="package://3D_model/AUBO_I10/meshes/I10Mesh.031.stl" scale="1 1 1"/>
      </geometry>
    </visual>
    <collision>
      <geometry>
        <mesh filename="package://3D_model/AUBO_I10/meshes/I10Mesh.031.stl" scale="1 1 1"/>
      </geometry>
    </collision>
  </link>

  <joint name="joint32" type="fixed">
    <parent link="link31"/>
    <child link="link32"/>
    <origin xyz="0 0 0" rpy="0 0 0"/>
  </joint>

  <!-- ==================== LINK33 (FINAL) ==================== -->
  <link name="link33">
    <inertial>
      <mass value="0.1"/>
      <inertia ixx="0.001" ixy="0" ixz="0"
               iyy="0.001" iyz="0" izz="0.001"/>
    </inertial>
    <visual>
      <geometry>
        <mesh filename="package://3D_model/AUBO_I10/meshes/I10Mesh.stl" scale="1 1 1"/>
      </geometry>
    </visual>
    <collision>
      <geometry>
        <mesh filename="package://3D_model/AUBO_I10/meshes/I10Mesh.stl" scale="1 1 1"/>
      </geometry>
    </collision>
  </link>

  <joint name="joint33" type="fixed">
    <parent link="link32"/>
    <child link="link33"/>
    <origin xyz="0 0 0" rpy="0 0 0"/>
  </joint>

</robot>
